Workbook

Sheet Dashboard
A1: Ross 308 Broiler Management Dashboard - Zambia
A3: Hatch Date: | B3: 46204
A4: Current Date: | B4: =TODAY()
A5: Target Market Age (days): | B5: 42
A6: Starting Chick Count: | B6: 1000
A7: Current Mortality (birds): | B7: 0
A9: Current Flock Age (days) | B9: =B4-B3 | G9: Management Reminders
A10: Days Until Market | B10: =B5-B9 | G10: Check temperature & humidity 2x daily
A11: Live Birds Remaining | B11: =B6-B7 | G11: Record mortality and culls daily
A12: Mortality Rate (%) | B12: =IF(B6=0,0,B7/B6) | G12: Monitor feed and water consumption
A13: Expected Target Weight (g) | B13: =IFERROR(VLOOKUP(B9,PerfData!$A$2:$F$51,2,FALSE),"") | G13: Inspect litter quality
A14: Expected Daily Feed Intake (g/bird) | B14: =IFERROR(VLOOKUP(B9,PerfData!$A$2:$F$51,4,FALSE),"") | G14: Verify cold chain for vaccines
A15: Expected Water Intake (mL/bird) | B15: =IF(B14="","",B14*1.8) | G15: Maintain footbaths and biosecurity
A17: Upcoming Vaccinations (Next 14 Days)
A18: Date | B18: Bird Age | C18: Vaccine | D18: Disease | E18: Route
A19: =IFERROR(B3+INDEX('Vaccination Calendar'!$A$2:$A$9,MATCH(TRUE,'Vaccination Calendar'!$A$2:$A$9>=(B9-1),0)),"") | B19: =IFERROR(INDEX('Vaccination Calendar'!$B$2:$B$9,MATCH(TRUE,'Vaccination Calendar'!$A$2:$A$9>=(B9-1),0)),"")
A20: =IFERROR(B3+INDEX('Vaccination Calendar'!$A$2:$A$9,MATCH(TRUE,'Vaccination Calendar'!$A$2:$A$9>=(B9-1),0)),"") | B20: =IFERROR(INDEX('Vaccination Calendar'!$B$2:$B$9,MATCH(TRUE,'Vaccination Calendar'!$A$2:$A$9>=(B9-1),0)),"")
A21: =IFERROR(B3+INDEX('Vaccination Calendar'!$A$2:$A$9,MATCH(TRUE,'Vaccination Calendar'!$A$2:$A$9>=(B9-1),0)),"") | B21: =IFERROR(INDEX('Vaccination Calendar'!$B$2:$B$9,MATCH(TRUE,'Vaccination Calendar'!$A$2:$A$9>=(B9-1),0)),"")
A22: =IFERROR(B3+INDEX('Vaccination Calendar'!$A$2:$A$9,MATCH(TRUE,'Vaccination Calendar'!$A$2:$A$9>=(B9-1),0)),"") | B22: =IFERROR(INDEX('Vaccination Calendar'!$B$2:$B$9,MATCH(TRUE,'Vaccination Calendar'!$A$2:$A$9>=(B9-1),0)),"")
A23: =IFERROR(B3+INDEX('Vaccination Calendar'!$A$2:$A$9,MATCH(TRUE,'Vaccination Calendar'!$A$2:$A$9>=(B9-1),0)),"") | B23: =IFERROR(INDEX('Vaccination Calendar'!$B$2:$B$9,MATCH(TRUE,'Vaccination Calendar'!$A$2:$A$9>=(B9-1),0)),"")

Sheet PerfData
A1: Day | B1: Weight(g) | C1: DailyGain(g) | D1: DailyIntake(g) | E1: CumIntake(g) | F1: FCR
A2: 0 | B2: 44 | C2: 0 | D2: 0 | E2: 0
A3: 1 | B3: 63 | C3: 19 | D3: 13 | E3: 13 | F3: 0.206
A4: 2 | B4: 81 | C4: 19 | D4: 17 | E4: 31 | F4: 0.375
A5: 3 | B5: 103 | C5: 21 | D5: 21 | E5: 52 | F5: 0.503
A6: 4 | B6: 126 | C6: 24 | D6: 25 | E6: 76 | F6: 0.604
A7: 5 | B7: 152 | C7: 26 | D7: 28 | E7: 104 | F7: 0.684
A8: 6 | B8: 182 | C8: 29 | D8: 32 | E8: 136 | F8: 0.748
A9: 7 | B9: 214 | C9: 32 | D9: 35 | E9: 171 | F9: 0.8
A10: 8 | B10: 249 | C10: 35 | D10: 39 | E10: 210 | F10: 0.843
A11: 9 | B11: 287 | C11: 38 | D11: 43 | E11: 253 | F11: 0.88
A12: 10 | B12: 328 | C12: 41 | D12: 47 | E12: 304 | F12: 0.947
A13: 11 | B13: 366 | C13: 44 | D13: 52 | E13: 358 | F13: 0.979
A14: 12 | B14: 414 | C14: 48 | D14: 58 | E14: 416 | F14: 1.007
... A51: 49 | B51: 3583 | C51: 93 | D51: 231 | E51: 6270 | F51: 1.75

Sheet Hatch Calculator
A1: Hatch Date Calculator
A3: Hatch Date: | B3: =Dashboard!B3
A5: Event | B5: Date | C5: Notes | D5: Age (days)
A6: Brooding starts / chick placement | B6: =B3+0 | C6: Set house at 30°C, 60-70% RH | D6: 0
A7: First feed and water check | B7: =B3+1 | C7: Ensure crop fill >95% by 24h | D7: 1
A8: Hatchery vaccines given (if applicable) | B8: =B3+1 | C8: Marek's, ND, IB, IBD immune-complex | D8: 1
A9: Switch from paper to auto feeders/drinkers | B9: =B3+4 | C9: Transition over 1-2 days | D9: 4
A10: Temperature reduced to 27°C | B10: =B3+6 | C10: Monitor chick behavior | D10: 6
A11: IB + ND booster (high challenge) | B11: =B3+10 | C11: Drinking water or spray | D11: 10
A12: Grower feed starts | B12: =B3+11 | C12: Transition gradually over 3 days | D12: 11
A13: Gumboro (IBD) live vaccine | B13: =B3+14 | C13: If no immune-complex used | D13: 14
A14: Temperature 22°C | B14: =B3+21 | C14: Ensure ventilation adequate | D14: 21
A15: ND booster | B15: =B3+21 | C15: Drinking water | D15: 21
A16: Finisher feed starts | B16: =B3+25 | C16: Adjust to market target | D16: 25
A17: Pre-slaughter withdrawal (coccidiostats) | B17: =B3+35 | C17: Check label withdrawal | D17: 35
A18: Market / processing date | B18: =B3+42 | C18: Target live weight 2.3-2.5 kg | D18: 42

Sheet Vaccination Calendar
A1: Vaccination Calendar
A3: Hatch Date: | B3: =Dashboard!B3
A5: Day | B5: Bird Age | C5: Vaccine | D5: Disease | E5: Administration Method | F5: Booster | G5: Completed | H5: Batch Number | I5: Expiry Date | J5: Administrator | K5: Notes
A6: 1 | B6: Day-old | C6: Marek's disease vaccine | D6: Marek's disease | E6: In ovo / Subcutaneous | F6: No | G6: No | K6: Hatchery standard
A7: 1 | B7: Day-old | C7: ND + IB (e.g., Nobilis ND C2 + IB Ma5) | D7: Newcastle + Infectious Bronchitis | E7: Coarse spray / Eye drop | F7: Yes | G7: No | K7: Hatchery preferred
A8: 1 | B8: Day-old | C8: IBD immune-complex (e.g., Transmune) | D8: Gumboro (IBD) | E8: Subcutaneous / In ovo | F8: No | G8: No | K8: If hatchery service available
A9: 1 | B9: Day-old | C9: Coccidiosis vaccine (e.g., Fortegra) | D9: Coccidiosis | E9: Coarse spray / Gel | F9: No | G9: No | K9: Optional if bio-shuttle program
A10: 10 | B10: 10 days | C10: IB + ND booster (e.g., Nobilis IB MA5 + Clone 30) | D10: Infectious Bronchitis + Newcastle | E10: Drinking water / Spray | F10: No | G10: No | K10: High-challenge areas
A11: 14 | B11: 14 days | C11: IBD live (e.g., Nobilis Gumboro D78) | D11: Gumboro (IBD) | E11: Drinking water | F11: No | G11: No | K11: If not using immune-complex
A12: 21 | B12: 21 days | C12: ND booster (e.g., Clone 30 / LaSota) | D12: Newcastle disease | E12: Drinking water | F12: No | G12: No | K12: Critical in high-challenge areas
A13: 28 | B13: 28 days | C13: ND booster (LaSota) | D13: Newcastle disease | E13: Drinking water | F13: No | G13: No | K13: Only if kept >42 days

Sheet Daily Checklist
A1: Daily Checklist - Day 0 to Day 49
A3: Hatch Date: | B3: =Dashboard!B3
A5: Day | B5: Date | C5: Morning Checks | D5: Evening Checks | E5: Feed/Water | F5: Done | G5: Notes
A6: 0 | B6: =B3+0 | C6: Check crop fill; temp/humidity; litter; water temp; chick activity | D6: Check crop fill; temp/humidity; mortality; adjust brooders | E6: Record feed delivered & consumed; record water consumption; check drinkers/nipples | F6: No
A7: 1 | B7: =B3+1 | C7: Check crop fill; temp/humidity; litter; water temp; chick activity | D7: Check crop fill; temp/humidity; mortality; adjust brooders | E7: Record feed delivered & consumed; record water consumption; check drinkers/nipples; Hatchery vaccines administered; record batch numbers | F7: No
A8: 2 | B8: =B3+2 | C8: Check crop fill; temp/humidity; litter; water temp; chick activity | D8: Check crop fill; temp/humidity; mortality; adjust brooders | E8: Record feed delivered & consumed; record water consumption; check drinkers/nipples | F8: No
A9: 3 | B9: =B3+3 | C9: Check crop fill; temp/humidity; litter; water temp; chick activity | D9: Check crop fill; temp/humidity; mortality; adjust brooders | E9: Record feed delivered & consumed; record water consumption; check drinkers/nipples | F9: No
A10: 4 | B10: =B3+4 | C10: Temp/humidity; water/feed levels; litter; mortality; culls; ventilation | D10: Temp/humidity; water/feed; mortality; litter; light intensity | E10: Record feed delivered & consumed; record water consumption; check drinkers/nipples | F10: No
A11: 5 | B11: =B3+5 | C11: Temp/humidity; water/feed levels; litter; mortality; culls; ventilation | D11: Temp/humidity; water/feed; mortality; litter; light intensity | E11: Record feed delivered & consumed; record water consumption; check drinkers/nipples | F11: No
A12: 6 | B12: =B3+6 | C12: Temp/humidity; water/feed levels; litter; mortality; culls; ventilation | D12: Temp/humidity; water/feed; mortality; litter; light intensity | E12: Record feed delivered & consumed; record water consumption; check drinkers/nipples | F12: No
A13: 7 | B13: =B3+7 | C13: Temp/humidity; water/feed levels; litter; mortality; culls; ventilation | D13: Temp/humidity; water/feed; mortality; litter; light intensity | E13: Record feed delivered & consumed; record water consumption; check drinkers/nipples | F13: No
A14: 8 | B14: =B3+8 | C14: Temp/humidity; water/feed levels; litter; mortality; culls; ventilation | D14: Temp/humidity; water/feed; mortality; litter; light intensity | E14: Record feed delivered & consumed; record water consumption; check drinkers/nipples | F14: No
A15: 9 | B15: =B3+9 | C15: Temp/humidity; water/feed levels; litter; mortality; culls; ventilation | D15: Temp/humidity; water/feed; mortality; litter; light intensity | E15: Record feed delivered & consumed; record water consumption; check drinkers/nipples | F15: No
A16: 10 | B16: =B3+10 | C16: Temp/humidity; water/feed levels; litter; mortality; culls; ventilation | D16: Temp/humidity; water/feed; mortality; litter; light intensity | E16: Record feed delivered & consumed; record water consumption; check drinkers/nipples; IB + ND booster if due | F16: No
A17: 11 | B17: =B3+11 | C17: Temp/humidity; water/feed levels; litter; mortality; culls; ventilation | D17: Temp/humidity; water/feed; mortality; litter; light intensity | E17: Record feed delivered & consumed; record water consumption; check drinkers/nipples | F17: No
A18: 12 | B18: =B3+12 | C18: Temp/humidity; water/feed levels; litter; mortality; culls; ventilation | D18: Temp/humidity; water/feed; mortality; litter; light intensity | E18: Record feed delivered & consumed; record water consumption; check drinkers/nipples | F18: No
A19: 13 | B19: =B3+13 | C19: Temp/humidity; water/feed levels; litter; mortality; culls; ventilation | D19: Temp/humidity; water/feed; mortality; litter; light intensity | E19: Record feed delivered & consumed; record water consumption; check drinkers/nipples | F19: No
A20: 14 | B20: =B3+14 | C20: Temp/humidity; water/feed levels; litter; mortality; culls; ventilation | D20: Temp/humidity; water/feed; mortality; litter; light intensity | E20: Record feed delivered & consumed; record water consumption; check drinkers/nipples; IBD live vaccine if due | F20: No
A21: 15 | B21: =B3+15 | C21: Temp/humidity; water/feed; litter; mortality; FCR check; ventilation | D21: Temp/humidity; water/feed; mortality; litter; inspect birds | E21: Record feed delivered & consumed; record water consumption; check drinkers/nipples | F21: No
A22: 16 | B22: =B3+16 | C22: Temp/humidity; water/feed; litter; mortality; FCR check; ventilation | D22: Temp/humidity; water/feed; mortality; litter; inspect birds | E22: Record feed delivered & consumed; record water consumption; check drinkers/nipples | F22: No
A23: 17 | B23: =B3+17 | C23: Temp/humidity; water/feed; litter; mortality; FCR check; ventilation | D23: Temp/humidity; water/feed; mortality; litter; inspect birds | E23: Record feed delivered & consumed; record water consumption; check drinkers/nipples | F23: No
A24: 18 | B24: =B3+18 | C24: Temp/humidity; water/feed; litter; mortality; FCR check; ventilation | D24: Temp/humidity; water/feed; mortality; litter; inspect birds | E24: Record feed delivered & consumed; record water consumption; check drinkers/nipples | F24: No
A25: 19 | B25: =B3+19 | C25: Temp/humidity; water/feed; litter; mortality; FCR check; ventilation | D25: Temp/humidity; water/feed; mortality; litter; inspect birds | E25: Record feed delivered & consumed; record water consumption; check drinkers/nipples | F25: No
A26: 20 | B26: =B3+20 | C26: Temp/humidity; water/feed; litter; mortality; FCR check; ventilation | D26: Temp/humidity; water/feed; mortality; litter; inspect birds | E26: Record feed delivered & consumed; record water consumption; check drinkers/nipples | F26: No
A27: 21 | B27: =B3+21 | C27: Temp/humidity; water/feed; litter; mortality; FCR check; ventilation | D27: Temp/humidity; water/feed; mortality; litter; inspect birds | E27: Record feed delivered & consumed; record water consumption; check drinkers/nipples; ND booster if due | F27: No
A28: 22 | B28: =B3+22 | C28: Temp/humidity; water/feed; litter; mortality; FCR check; ventilation | D28: Temp/humidity; water/feed; mortality; litter; inspect birds | E28: Record feed delivered & consumed; record water consumption; check drinkers/nipples | F28: No
A29: 23 | B29: =B3+23 | C29: Temp/humidity; water/feed; litter; mortality; FCR check; ventilation | D29: Temp/humidity; water/feed; mortality; litter; inspect birds | E29: Record feed delivered & consumed; record water consumption; check drinkers/nipples | F29: No
A30: 24 | B30: =B3+24 | C30: Temp/humidity; water/feed; litter; mortality; FCR check; ventilation | D30: Temp/humidity; water/feed; mortality; litter; inspect birds | E30: Record feed delivered & consumed; record water consumption; check drinkers/nipples | F30: No
A31: 25 | B31: =B3+25 | C31: Temp/humidity; water/feed; litter; mortality; FCR check; ventilation | D31: Temp/humidity; water/feed; mortality; litter; inspect birds | E31: Record feed delivered & consumed; record water consumption; check drinkers/nipples | F31: No
A32: 26 | B32: =B3+26 | C32: Temp/humidity; water/feed; litter; mortality; FCR check; ventilation | D32: Temp/humidity; water/feed; mortality; litter; inspect birds | E32: Record feed delivered & consumed; record water consumption; check drinkers/nipples | F32: No
A33: 27 | B33: =B3+27 | C33: Temp/humidity; water/feed; litter; mortality; FCR check; ventilation | D33: Temp/humidity; water/feed; mortality; litter; inspect birds | E33: Record feed delivered & consumed; record water consumption; check drinkers/nipples | F33: No
A34: 28 | B34: =B3+28 | C34: Temp/humidity; water/feed; litter; mortality; FCR check; ventilation | D34: Temp/humidity; water/feed; mortality; litter; inspect birds | E34: Record feed delivered & consumed; record water consumption; check drinkers/nipples; ND booster if keeping >42 days | F34: No
A35: 29 | B35: =B3+29 | C35: Temp/humidity; water/feed; litter; mortality; pre-slaughter checks | D35: Temp/humidity; water/feed; mortality; litter; ventilation fans | E35: Record feed delivered & consumed; record water consumption; check drinkers/nipples | F35: No
A36: 30 | B36: =B3+30 | C36: Temp/humidity; water/feed; litter; mortality; pre-slaughter checks | D36: Temp/humidity; water/feed; mortality; litter; ventilation fans | E36: Record feed delivered & consumed; record water consumption; check drinkers/nipples | F36: No
A37: 31 | B37: =B3+31 | C37: Temp/humidity; water/feed; litter; mortality; pre-slaughter checks | D37: Temp/humidity; water/feed; mortality; litter; ventilation fans | E37: Record feed delivered & consumed; record water consumption; check drinkers/nipples | F37: No
A38: 32 | B38: =B3+32 | C38: Temp/humidity; water/feed; litter; mortality; pre-slaughter checks | D38: Temp/humidity; water/feed; mortality; litter; ventilation fans | E38: Record feed delivered & consumed; record water consumption; check drinkers/nipples | F38: No
A39: 33 | B39: =B3+33 | C39: Temp/humidity; water/feed; litter; mortality; pre-slaughter checks | D39: Temp/humidity; water/feed; mortality; litter; ventilation fans | E39: Record feed delivered & consumed; record water consumption; check drinkers/nipples | F39: No
A40: 34 | B40: =B3+34 | C40: Temp/humidity; water/feed; litter; mortality; pre-slaughter checks | D40: Temp/humidity; water/feed; mortality; litter; ventilation fans | E40: Record feed delivered & consumed; record water consumption; check drinkers/nipples | F40: No
A41: 35 | B41: =B3+35 | C41: Temp/humidity; water/feed; litter; mortality; pre-slaughter checks | D41: Temp/humidity; water/feed; mortality; litter; ventilation fans | E41: Record feed delivered & consumed; record water consumption; check drinkers/nipples; Check medication withdrawal periods | F41: No
A42: 36 | B42: =B3+36 | C42: Temp/humidity; water/feed; litter; mortality; pre-slaughter checks | D42: Temp/humidity; water/feed; mortality; litter; ventilation fans | E42: Record feed delivered & consumed; record water consumption; check drinkers/nipples | F42: No
...

Sheet Weekly Weights
A1: Weekly Weights and Growth Monitoring
A3: Day | B3: Expected Wt (g) | C3: Actual Wt (g) | D3: Variance (g) | E3: Variance % | F3: Daily Gain | G3: Actual Daily Gain | H3: Uniformity CV% | I3: Notes
A4: 0 | B4: =IFERROR(VLOOKUP(A4,PerfData!$A$2:$B$51,2,FALSE),"") | D4: =IF(OR(C4="",B4=""),"",C4-B4) | E4: =IF(OR(C4="",B4="",B4=0),"",D4/B4) | F4: =IFERROR(VLOOKUP(A4,PerfData!$A$2:$C$51,3,FALSE),"") | G4: =IF(OR(C4="",A4=0),"",IF(A4=0,"",C4/A4))
A5: 7 | B5: =IFERROR(VLOOKUP(A5,PerfData!$A$2:$B$51,2,FALSE),"") | D5: =IF(OR(C5="",B5=""),"",C5-B5) | E5: =IF(OR(C5="",B5="",B5=0),"",D5/B5) | F5: =IFERROR(VLOOKUP(A5,PerfData!$A$2:$C$51,3,FALSE),"") | G5: =IF(OR(C5="",A5=0),"",IF(A5=0,"",C5/A5))
A6: 14 | B6: =IFERROR(VLOOKUP(A6,PerfData!$A$2:$B$51,2,FALSE),"") | D6: =IF(OR(C6="",B6=""),"",C6-B6) | E6: =IF(OR(C6="",B6="",B6=0),"",D6/B6) | F6: =IFERROR(VLOOKUP(A6,PerfData!$A$2:$C$51,3,FALSE),"") | G6: =IF(OR(C6="",A6=0),"",IF(A6=0,"",C6/A6))
A7: 21 | B7: =IFERROR(VLOOKUP(A7,PerfData!$A$2:$B$51,2,FALSE),"") | D7: =IF(OR(C7="",B7=""),"",C7-B7) | E7: =IF(OR(C7="",B7="",B7=0),"",D7/B7) | F7: =IFERROR(VLOOKUP(A7,PerfData!$A$2:$C$51,3,FALSE),"") | G7: =IF(OR(C7="",A7=0),"",IF(A7=0,"",C7/A7))
A8: 28 | B8: =IFERROR(VLOOKUP(A8,PerfData!$A$2:$B$51,2,FALSE),"") | D8: =IF(OR(C8="",B8=""),"",C8-B8) | E8: =IF(OR(C8="",B8="",B8=0),"",D8/B8) | F8: =IFERROR(VLOOKUP(A8,PerfData!$A$2:$C$51,3,FALSE),"") | G8: =IF(OR(C8="",A8=0),"",IF(A8=0,"",C8/A8))
A9: 35 | B9: =IFERROR(VLOOKUP(A9,PerfData!$A$2:$B$51,2,FALSE),"") | D9: =IF(OR(C9="",B9=""),"",C9-B9) | E9: =IF(OR(C9="",B9="",B9=0),"",D9/B9) | F9: =IFERROR(VLOOKUP(A9,PerfData!$A$2:$C$51,3,FALSE),"") | G9: =IF(OR(C9="",A9=0),"",IF(A9=0,"",C9/A9))
A10: 42 | B10: =IFERROR(VLOOKUP(A10,PerfData!$A$2:$B$51,2,FALSE),"") | D10: =IF(OR(C10="",B10=""),"",C10-B10) | E10: =IF(OR(C10="",B10="",B10=0),"",D10/B10) | F10: =IFERROR(VLOOKUP(A10,PerfData!$A$2:$C$51,3,FALSE),"") | G10: =IF(OR(C10="",A10=0),"",IF(A10=0,"",C10/A10))
A11: 49 | B11: =IFERROR(VLOOKUP(A11,PerfData!$A$2:$B$51,2,FALSE),"") | D11: =IF(OR(C11="",B11=""),"",C11-B11) | E11: =IF(OR(C11="",B11="",B11=0),"",D11/B11) | F11: =IFERROR(VLOOKUP(A11,PerfData!$A$2:$C$51,3,FALSE),"") | G11: =IF(OR(C11="",A11=0),"",IF(A11=0,"",C11/A11))

Sheet Feed Tracking
A1: Feed Tracking
A3: Day | B3: Feed Type | C3: Feed Delivered (kg) | D3: Opening Stock (kg) | E3: Feed Consumed (kg) | F3: Closing Stock (kg) | G3: Birds | H3: Feed per Bird (g) | I3: Cumulative FCR
A4: 2 | B4: Pre-starter | C4: 0 | D4: =IF(C4=0,0,IF(row=4,0,D3+C4-E3)) | E4: 0 | F4: =D4-E4 | G4: =Dashboard!$B$11 | H4: =IF(G4=0,0,E4*1000/G4) | I4: =IFERROR(VLOOKUP(A4,PerfData!$A$2:$F$51,6,FALSE),"")
A5: 7 | B5: Starter | C5: 0 | D5: =IF(C5=0,0,IF(row=4,0,D4+C5-E4)) | E5: 0 | F5: =D5-E5 | G5: =Dashboard!$B$11 | H5: =IF(G5=0,0,E5*1000/G5) | I5: =IFERROR(VLOOKUP(A5,PerfData!$A$2:$F$51,6,FALSE),"")
A6: 12 | B6: Starter | C6: 0 | D6: =IF(C6=0,0,IF(row=4,0,D5+C6-E5)) | E6: 0 | F6: =D6-E6 | G6: =Dashboard!$B$11 | H6: =IF(G6=0,0,E6*1000/G6) | I6: =IFERROR(VLOOKUP(A6,PerfData!$A$2:$F$51,6,FALSE),"")
A7: 17 | B7: Grower | C7: 0 | D7: =IF(C7=0,0,IF(row=4,0,D6+C7-E6)) | E7: 0 | F7: =D7-E7 | G7: =Dashboard!$B$11 | H7: =IF(G7=0,0,E7*1000/G7) | I7: =IFERROR(VLOOKUP(A7,PerfData!$A$2:$F$51,6,FALSE),"")
A8: 22 | B8: Grower | C8: 0 | D8: =IF(C8=0,0,IF(row=4,0,D7+C8-E7)) | E8: 0 | F8: =D8-E8 | G8: =Dashboard!$B$11 | H8: =IF(G8=0,0,E8*1000/G8) | I8: =IFERROR(VLOOKUP(A8,PerfData!$A$2:$F$51,6,FALSE),"")
A9: 27 | B9: Grower | C9: 0 | D9: =IF(C9=0,0,IF(row=4,0,D8+C9-E8)) | E9: 0 | F9: =D9-E9 | G9: =Dashboard!$B$11 | H9: =IF(G9=0,0,E9*1000/G9) | I9: =IFERROR(VLOOKUP(A9,PerfData!$A$2:$F$51,6,FALSE),"")
A10: 32 | B10: Finisher 1 | C10: 0 | D10: =IF(C10=0,0,IF(row=4,0,D9+C10-E9)) | E10: 0 | F10: =D10-E10 | G10: =Dashboard!$B$11 | H10: =IF(G10=0,0,E10*1000/G10) | I10: =IFERROR(VLOOKUP(A10,PerfData!$A$2:$F$51,6,FALSE),"")
A11: 37 | B11: Finisher 1 | C11: 0 | D11: =IF(C11=0,0,IF(row=4,0,D10+C11-E10)) | E11: 0 | F11: =D11-E11 | G11: =Dashboard!$B$11 | H11: =IF(G11=0,0,E11*1000/G11) | I11: =IFERROR(VLOOKUP(A11,PerfData!$A$2:$F$51,6,FALSE),"")
A12: 42 | B12: Finisher 1 | C12: 0 | D12: =IF(C12=0,0,IF(row=4,0,D11+C12-E11)) | E12: 0 | F12: =D12-E12 | G12: =Dashboard!$B$11 | H12: =IF(G12=0,0,E12*1000/G12) | I12: =IFERROR(VLOOKUP(A12,PerfData!$A$2:$F$51,6,FALSE),"")
A13: 47 | B13: Finisher 2 | C13: 0 | D13: =IF(C13=0,0,IF(row=4,0,D12+C13-E12)) | E13: 0 | F13: =D13-E13 | G13: =Dashboard!$B$11 | H13: =IF(G13=0,0,E13*1000/G13) | I13: =IFERROR(VLOOKUP(A13,PerfData!$A$2:$F$51,6,FALSE),"")

Sheet Water Tracking
A1: Water Tracking
A3: Day | B3: Temp (°C) | C3: Expected Water (L) | D3: Actual Water (L) | E3: Water:Feed Ratio | F3: Deviation | G3: Status | H3: Notes
A4: 2 | B4: 25 | C4: =IFERROR(VLOOKUP(A4,PerfData!$A$2:$D$51,4,FALSE)*1.8/1000*Dashboard!$B$11*(1+MAX(0,B4-21)*0.06),0) | D4: 0 | E4: =IFERROR(D4/(VLOOKUP(A4,PerfData!$A$2:$D$51,4,FALSE)/1000*Dashboard!$B$11),0) | F4: =D4-C4 | G4: =IF(ABS(F4)/C4>0.15,"Check!","Normal")
A5: 7 | B5: 25 | C5: =IFERROR(VLOOKUP(A5,PerfData!$A$2:$D$51,4,FALSE)*1.8/1000*Dashboard!$B$11*(1+MAX(0,B5-21)*0.06),0) | D5: 0 | E5: =IFERROR(D5/(VLOOKUP(A5,PerfData!$A$2:$D$51,4,FALSE)/1000*Dashboard!$B$11),0) | F5: =D5-C5 | G5: =IF(ABS(F5)/C5>0.15,"Check!","Normal")
A6: 12 | B6: 25 | C6: =IFERROR(VLOOKUP(A6,PerfData!$A$2:$D$51,4,FALSE)*1.8/1000*Dashboard!$B$11*(1+MAX(0,B6-21)*0.06),0) | D6: 0 | E6: =IFERROR(D6/(VLOOKUP(A6,PerfData!$A$2:$D$51,4,FALSE)/1000*Dashboard!$B$11),0) | F6: =D6-C6 | G6: =IF(ABS(F6)/C6>0.15,"Check!","Normal")
A7: 17 | B7: 25 | C7: =IFERROR(VLOOKUP(A7,PerfData!$A$2:$D$51,4,FALSE)*1.8/1000*Dashboard!$B$11*(1+MAX(0,B7-21)*0.06),0) | D7: 0 | E7: =IFERROR(D7/(VLOOKUP(A7,PerfData!$A$2:$D$51,4,FALSE)/1000*Dashboard!$B$11),0) | F7: =D7-C7 | G7: =IF(ABS(F7)/C7>0.15,"Check!","Normal")
A8: 22 | B8: 25 | C8: =IFERROR(VLOOKUP(A8,PerfData!$A$2:$D$51,4,FALSE)*1.8/1000*Dashboard!$B$11*(1+MAX(0,B8-21)*0.06),0) | D8: 0 | E8: =IFERROR(D8/(VLOOKUP(A8,PerfData!$A$2:$D$51,4,FALSE)/1000*Dashboard!$B$11),0) | F8: =D8-C8 | G8: =IF(ABS(F8)/C8>0.15,"Check!","Normal")
A9: 27 | B9: 25 | C9: =IFERROR(VLOOKUP(A9,PerfData!$A$2:$D$51,4,FALSE)*1.8/1000*Dashboard!$B$11*(1+MAX(0,B9-21)*0.06),0) | D9: 0 | E9: =IFERROR(D9/(VLOOKUP(A9,PerfData!$A$2:$D$51,4,FALSE)/1000*Dashboard!$B$11),0) | F9: =D9-C9 | G9: =IF(ABS(F9)/C9>0.15,"Check!","Normal")
A10: 32 | B10: 25 | C10: =IFERROR(VLOOKUP(A10,PerfData!$A$2:$D$51,4,FALSE)*1.8/1000*Dashboard!$B$11*(1+MAX(0,B10-21)*0.06),0) | D10: 0 | E10: =IFERROR(D10/(VLOOKUP(A10,PerfData!$A$2:$D$51,4,FALSE)/1000*Dashboard!$B$11),0) | F10: =D10-C10 | G10: =IF(ABS(F10)/C10>0.15,"Check!","Normal")
A11: 37 | B11: 25 | C11: =IFERROR(VLOOKUP(A11,PerfData!$A$2:$D$51,4,FALSE)*1.8/1000*Dashboard!$B$11*(1+MAX(0,B11-21)*0.06),0) | D11: 0 | E11: =IFERROR(D11/(VLOOKUP(A11,PerfData!$A$2:$D$51,4,FALSE)/1000*Dashboard!$B$11),0) | F11: =D11-C11 | G11: =IF(ABS(F11)/C11>0.15,"Check!","Normal")
A12: 42 | B12: 25 | C12: =IFERROR(VLOOKUP(A12,PerfData!$A$2:$D$51,4,FALSE)*1.8/1000*Dashboard!$B$11*(1+MAX(0,B12-21)*0.06),0) | D12: 0 | E12: =IFERROR(D12/(VLOOKUP(A12,PerfData!$A$2:$D$51,4,FALSE)/1000*Dashboard!$B$11),0) | F12: =D12-C12 | G12: =IF(ABS(F12)/C12>0.15,"Check!","Normal")
A13: 47 | B13: 25 | C13: =IFERROR(VLOOKUP(A13,PerfData!$A$2:$D$51,4,FALSE)*1.8/1000*Dashboard!$B$11*(1+MAX(0,B13-21)*0.06),0) | D13: 0 | E13: =IFERROR(D13/(VLOOKUP(A13,PerfData!$A$2:$D$51,4,FALSE)/1000*Dashboard!$B$11),0) | F13: =D13-C13 | G13: =IF(ABS(F13)/C13>0.15,"Check!","Normal")

Sheet Mortality Log
A1: Mortality Log
A3: Date | B3: Day | C3: Age | D3: Dead Birds | E3: Cumulative | F3: Mortality % | G3: Suspected Cause | H3: Post-Mortem Findings | I3: Notes
B4: =IF(A4="","",A4-Dashboard!$B$3) | C4: =IF(B4="","",B4) | D4: 0 | E4: =SUM($D$4:D4) | F4: =IF(Dashboard!$B$6=0,0,E4/Dashboard!$B$6)
B5: =IF(A5="","",A5-Dashboard!$B$3) | C5: =IF(B5="","",B5) | D5: 0 | E5: =SUM($D$4:D5) | F5: =IF(Dashboard!$B$6=0,0,E5/Dashboard!$B$6)
B6: =IF(A6="","",A6-Dashboard!$B$3) | C6: =IF(B6="","",B6) | D6: 0 | E6: =SUM($D$4:D6) | F6: =IF(Dashboard!$B$6=0,0,E6/Dashboard!$B$6)
B7: =IF(A7="","",A7-Dashboard!$B$3) | C7: =IF(B7="","",B7) | D7: 0 | E7: =SUM($D$4:D7) | F7: =IF(Dashboard!$B$6=0,0,E7/Dashboard!$B$6)
B8: =IF(A8="","",A8-Dashboard!$B$3) | C8: =IF(B8="","",B8) | D8: 0 | E8: =SUM($D$4:D8) | F8: =IF(Dashboard!$B$6=0,0,E8/Dashboard!$B$6)
B9: =IF(A9="","",A9-Dashboard!$B$3) | C9: =IF(B9="","",B9) | D9: 0 | E9: =SUM($D$4:D9) | F9: =IF(Dashboard!$B$6=0,0,E9/Dashboard!$B$6)
B10: =IF(A10="","",A10-Dashboard!$B$3) | C10: =IF(B10="","",B10) | D10: 0 | E10: =SUM($D$4:D10) | F10: =IF(Dashboard!$B$6=0,0,E10/Dashboard!$B$6)
B11: =IF(A11="","",A11-Dashboard!$B$3) | C11: =IF(B11="","",B11) | D11: 0 | E11: =SUM($D$4:D11) | F11: =IF(Dashboard!$B$6=0,0,E11/Dashboard!$B$6)
B12: =IF(A12="","",A12-Dashboard!$B$3) | C12: =IF(B12="","",B12) | D12: 0 | E12: =SUM($D$4:D12) | F12: =IF(Dashboard!$B$6=0,0,E12/Dashboard!$B$6)
B13: =IF(A13="","",A13-Dashboard!$B$3) | C13: =IF(B13="","",B13) | D13: 0 | E13: =SUM($D$4:D13) | F13: =IF(Dashboard!$B$6=0,0,E13/Dashboard!$B$6)
B14: =IF(A14="","",A14-Dashboard!$B$3) | C14: =IF(B14="","",B14) | D14: 0 | E14: =SUM($D$4:D14) | F14: =IF(Dashboard!$B$6=0,0,E14/Dashboard!$B$6)
B15: =IF(A15="","",A15-Dashboard!$B$3) | C15: =IF(B15="","",B15) | D15: 0 | E15: =SUM($D$4:D15) | F15: =IF(Dashboard!$B$6=0,0,E15/Dashboard!$B$6)
... B33: =IF(A33="","",A33-Dashboard!$B$3) | C33: =IF(B33="","",B33) | D33: 0 | E33: =SUM($D$4:D33) | F33: =IF(Dashboard!$B$6=0,0,E33/Dashboard!$B$6)

Sheet Medication Register
A1: Medication Register
A3: Medicine | B3: Purpose | C3: Start Date | D3: End Date | E3: Withdrawal (days) | F3: Dose | G3: Route | H3: Completed | I3: Veterinarian
H4: No
H5: No
H6: No
H7: No
H8: No
H9: No
H10: No
H11: No
H12: No
H13: No
H14: No
H15: No
... H18: No

Sheet Vaccine Inventory
A1: Vaccine Inventory
A3: Vaccine | B3: Manufacturer | C3: Lot Number | D3: Expiry Date | E3: Storage Temp (°C) | F3: Quantity Received | G3: Quantity Used | H3: Quantity Remaining | I3: Alert | J3: Notes
H4: =IFERROR(F4-G4,0) | I4: =IF(D4="","",IF(D4-TODAY()<30,"EXPIRING SOON","OK"))
H5: =IFERROR(F5-G5,0) | I5: =IF(D5="","",IF(D5-TODAY()<30,"EXPIRING SOON","OK"))
H6: =IFERROR(F6-G6,0) | I6: =IF(D6="","",IF(D6-TODAY()<30,"EXPIRING SOON","OK"))
H7: =IFERROR(F7-G7,0) | I7: =IF(D7="","",IF(D7-TODAY()<30,"EXPIRING SOON","OK"))
H8: =IFERROR(F8-G8,0) | I8: =IF(D8="","",IF(D8-TODAY()<30,"EXPIRING SOON","OK"))
H9: =IFERROR(F9-G9,0) | I9: =IF(D9="","",IF(D9-TODAY()<30,"EXPIRING SOON","OK"))
H10: =IFERROR(F10-G10,0) | I10: =IF(D10="","",IF(D10-TODAY()<30,"EXPIRING SOON","OK"))
H11: =IFERROR(F11-G11,0) | I11: =IF(D11="","",IF(D11-TODAY()<30,"EXPIRING SOON","OK"))
H12: =IFERROR(F12-G12,0) | I12: =IF(D12="","",IF(D12-TODAY()<30,"EXPIRING SOON","OK"))
H13: =IFERROR(F13-G13,0) | I13: =IF(D13="","",IF(D13-TODAY()<30,"EXPIRING SOON","OK"))
H14: =IFERROR(F14-G14,0) | I14: =IF(D14="","",IF(D14-TODAY()<30,"EXPIRING SOON","OK"))
H15: =IFERROR(F15-G15,0) | I15: =IF(D15="","",IF(D15-TODAY()<30,"EXPIRING SOON","OK"))
... H18: =IFERROR(F18-G18,0) | I18: =IF(D18="","",IF(D18-TODAY()<30,"EXPIRING SOON","OK"))

Sheet Farm Records
A1: Farm Records
A3: Date | B3: Weather | C3: Notes | D3: Biosecurity Incidents | E3: Maintenance
